Traceback (most recent call last):
  File "/home/artemi/.local/lib/python3.10/site-packages/myst_nb/core/execute/inline.py", line 128, in code_cell_outputs
    self._client.execute_cell(
  File "/home/artemi/.local/lib/python3.10/site-packages/jupyter_core/utils/__init__.py", line 165, in wrapped
    return loop.run_until_complete(inner)
  File "/usr/lib/python3.10/asyncio/base_events.py", line 649, in run_until_complete
    return future.result()
  File "/home/artemi/.local/lib/python3.10/site-packages/nbclient/client.py", line 1062, in async_execute_cell
    await self._check_raise_for_error(cell, cell_index, exec_reply)
  File "/home/artemi/.local/lib/python3.10/site-packages/nbclient/client.py", line 918, in _check_raise_for_error
    raise CellExecutionError.from_cell_and_msg(cell, exec_reply_content)
nbclient.exceptions.CellExecutionError: An error occurred while executing the following cell:
------------------

    
plaintext_path = "test_files/otp/target_plaintext.txt"

sys.argv = ["","-e", 
            "test_files/otp/target_plaintext.txt","-d", 
            "test_files/otp/target.txt", "-p","test_files/otp/otp.txt" 
            , "-c", "test_files/otp/c0.txt" , "-t", "test_files/otp/target.txt" 
            ]


main(sys.argv[1:])

------------------

----- stderr -----
usage: [-h] [-e ENCRYPT] [-d DECRYPT] [-p OTP] [-c CRYPTANALYSIS [CRYPTANALYSIS ...]] [-t TARGET] [-o OUTPUT]
: error: argument -e/--encrypt: can't open 'test_files/otp/target_plaintext.txt': [Errno 2] No such file or directory: 'test_files/otp/target_plaintext.txt'
----- stderr -----
/home/artemi/.local/lib/python3.10/site-packages/IPython/core/interactiveshell.py:3585: UserWarning: To exit: use 'exit', 'quit', or Ctrl-D.
  warn("To exit: use 'exit', 'quit', or Ctrl-D.", stacklevel=1)
------------------

An exception has occurred, use %tb to see the full traceback.

[0;31mSystemExit[0m[0;31m:[0m 2


